<?xml version="1.0"?>

  <robot name="ddmr1" xmlns:xacro="http://www.ros.org/wiki/xacro">
    <xacro:include filename="$(find ddmr_description)/urdf/ddmr.gazebo" />
    
    
    <link name="link_chassis_botom">
      <inertial>
        <origin xyz="0 0 0" rpy="0 0 0"/>
        <mass value="0.8"/>
        <inertia ixx="0.00336" ixy="0" ixz="0" iyy="0.00517" iyz="0" izz="0.00824"/>
      </inertial>
      <visual name="chassis_botom">
        <origin xyz="0 0 0" rpy="0 0 0"/>
        <geometry>
          <mesh filename="package://ddmr_description/meshes/dae/chassis_botom.dae" scale="1.0 1.0 1.0"/>
        </geometry>
        <material name="white_mat"/>
      </visual>
      <collision name="chassis_botom_col">
        <origin xyz="-0.00406 -4e-05 0.01198" rpy="0 0 0"/>
        <geometry>
          <box size="0.44516 0.32757 0.05975"/>
        </geometry>
      </collision>
    </link>

    <link name="link_chassis_top">
      <inertial>
        <origin xyz="0 0 0" rpy="0 0 0"/>
        <mass value="0.1"/>
        <inertia ixx="0.00135" ixy="0" ixz="0" iyy="0.00238" iyz="0" izz="0.00372"/>
      </inertial>
      <visual name="chassis_top">
        <origin xyz="0 0 0" rpy="0 0 0"/>
        <geometry>
          <mesh filename="package://ddmr_description/meshes/dae/chassis_top.dae" scale="1.0 1.0 1.0"/>
        </geometry>
        <material name="black_mat"/>
      </visual>
      <collision name="chassis_top_col">
        <origin xyz="-0.01362 -0.00255 0" rpy="0 0 0"/>
        <geometry>
          <box size="0.29395 0.31545 0.02122"/>
        </geometry>
      </collision>
    </link>

    <link name="link_front_wheel">
      <inertial>
        <origin xyz="0 0 0" rpy="0 0 0"/>
        <mass value="0.01"/>
        <inertia ixx="2e-05" ixy="0" ixz="0" iyy="2e-05" iyz="0" izz="2e-05"/>
      </inertial>
      <visual name="front_wheel">
        <origin xyz="0 0 0" rpy="-1.5708 0 0"/>
        <geometry>
          <mesh filename="package://ddmr_description/meshes/dae/front_wheel.dae" scale="1.0 1.0 1.0"/>
        </geometry>
        <material name="black_mat"/>
      </visual>
      <collision name="front_wheel_col">
        <origin xyz="0 0 0" rpy="0 0 0"/>
        <geometry>
          <cylinder radius="0.02339" length="0.01153"/>
        </geometry>
      </collision>
    </link>

    <link name="link_front_wheel_holder">
      <inertial>
        <origin xyz="-0.02896 0 -0.01695" rpy="0 0 0"/>
        <mass value="0.02"/>
        <inertia ixx="2e-05" ixy="0" ixz="0" iyy="2e-05" iyz="0" izz="2e-05"/>
      </inertial>
      <visual name="front_wheel_holder">
        <origin xyz="-0.01448 0 -0.00847" rpy="0 0 0"/>
        <geometry>
          <mesh filename="package://ddmr_description/meshes/dae/front_wheel_holder.dae" scale="1.0 1.0 1.0"/>
        </geometry>
        <material name="white_mat"/>
      </visual>
      <collision name="front_wheel_holder_col">
        <origin xyz="-0.01374 0 -0.00965" rpy="0 0 0"/>
        <geometry>
          <box size="0.04293 0.02094 0.04259"/>
        </geometry>
      </collision>
    </link>

    <link name="link_left_wheel">
      <inertial>
        <origin xyz="0 0 0" rpy="0 0 0"/>
        <mass value="0.2"/>
        <inertia ixx="0.00027" ixy="0" ixz="0" iyy="0.00052" iyz="0" izz="0.00027"/>
      </inertial>
      <visual name="right_wheel">
        <origin xyz="0 0 0" rpy="-1.5708 0 0"/>
        <geometry>
          <mesh filename="package://ddmr_description/meshes/dae/left_wheel.dae" scale="1.0 1.0 1.0"/>
        </geometry>
        <material name="black_mat"/>
      </visual>
      <collision name="left_wheel_col">
        <origin xyz="0 0 0.00368" rpy="0 0 0"/>
        <geometry>
          <cylinder radius="0.10072" length="0.05208"/>
        </geometry>
      </collision>
    </link>

    <link name="link_right_wheel">
      <inertial>
        <origin xyz="0 0 0" rpy="0 0 0"/>
        <mass value="0.11"/>
        <inertia ixx="0.00027" ixy="0" ixz="0" iyy="0.00052" iyz="0" izz="0.00027"/>
      </inertial>
      <visual name="right_wheel">
        <origin xyz="0 0 0" rpy="-1.5708 0 0"/>
        <geometry>
          <mesh filename="package://ddmr_description/meshes/dae/right_wheel.dae" scale="1.0 1.0 1.0"/>
        </geometry>
        <material name="white_mat"/>
      </visual>
      <collision name="right_wheel_col">
        <origin xyz="0 0 -0.00368" rpy="0 0 0"/>
        <geometry>
          <cylinder radius="0.10072" length="0.05208"/>
        </geometry>
      </collision>
    </link>

    <joint name="joint_chassis_top" type="fixed">
      <origin xyz="-0.06605 0 0.05247" rpy="0 0 0"/>
      <parent link="link_chassis_botom"/>
      <child link="link_chassis_top"/>
    </joint>

    <joint name="joint_front_wheel" type="continuous">
      <origin xyz="-0.02717 0.00013 -0.02589" rpy="1.5708 0 0"/>
      <parent link="link_front_wheel_holder"/>
      <child link="link_front_wheel"/>
      <axis xyz="0 0 1.0"/>
      <limit effort="1000.0" velocity="1000.0"/>
    </joint>

    <joint name="joint_front_wheel_holder" type="continuous">
      <origin xyz="0.13221 -0.0007 -0.02813" rpy="0 0 0"/>
      <parent link="link_chassis_botom"/>
      <child link="link_front_wheel_holder"/>
      <axis xyz="0 0 1.0"/>
      <limit effort="1000.0" velocity="1000.0"/>
    </joint>

    <joint name="joint_left_wheel" type="continuous">
      <origin xyz="-0.04 0.17354 0.022" rpy="1.5708 0 0"/>
      <parent link="link_chassis_botom"/>
      <child link="link_left_wheel"/>
      <axis xyz="0 0 -1.0"/>
      <limit effort="1000.0" velocity="1000.0"/>
    </joint>

    <joint name="joint_right_wheel" type="continuous">
      <origin xyz="-0.04 -0.17415 0.022" rpy="1.5708 0 0"/>
      <parent link="link_chassis_botom"/>
      <child link="link_right_wheel"/>
      <axis xyz="0 0 -1.0"/>
      <limit effort="1000.0" velocity="1000.0"/>
    </joint>

    <material name="black_mat">
      <color rgba="0 0 0 1.0"/>
    </material>

    <material name="white_mat">
      <color rgba="0.8 0.8 0.8 1.0"/>
    </material>

  </robot>
