<?xml version="1.0"?>


<robot xmlns:xacro="http://www.ros.org/wiki/xacro" name="spcrobot">

    <xacro:property name="cameraSize" value="0.05"/>
    <xacro:property name="cameraMass" value="0.1"/>

    <xacro:include filename="$(find spcbot_description)/urdf/materials.xacro" />
    <xacro:include filename="$(find spcbot_description)/urdf/spcbot.gazebo" />

    <link name="chassis">
        <pose>0 0 0.1 0 0 0</pose>
        <inertial>
            <origin xyz="0.0 0.0 0.1" rpy="0.0 0.0 0.0"/>
            <mass value="15.0"/>
            <inertia ixx="0.1" ixy="0.0" ixz="0.0" iyy="0.1" iyz="0.0" izz="0.1"/>
        </inertial>
        <visual name="chassis_visual">
            <origin xyz="0.0 0.0 0.0" rpy="0.0 0.0 0.0"/>
            <geometry>
                <box size="0.4 0.2 0.1"/>
            </geometry>
            <material name="blue"/>
        </visual>
        <collision>
            <origin xyz="0.0 0.0 0.0" rpy="0.0 0.0 0.0"/>
            <geometry>
                <box size="0.4 0.2 0.1"/>
            </geometry>
        </collision>
        <collision name="caster_collusion">
            <origin xyz="-0.15 0.0 -0.05" rpy="0.0 0.0 0.0"/>
            <geometry>
                <sphere radius="0.05"/>
            </geometry>
            <surface>
                <friction>
                    <ode>
                        <mu>0</mu>
                        <mu2>0</mu2>
                        <slip1>1.0</slip1>
                        <slip2>1.0</slip2>
                    </ode>
                </friction>
            </surface>
        </collision>

        <visual name="caster_visual">
            <origin xyz="-0.15 0.0 -0.05" rpy="0.0 0.0 0.0"/>
            <geometry>
                <sphere radius="0.05"/>
            </geometry>
        </visual>

        <collision name="caster_front_collusion">
            <origin xyz="0.15 0.0 -0.05" rpy="0.0 0.0 0.0"/>
            <geometry>
                <sphere radius="0.05"/>
            </geometry>

            <surface>
                <friction>
                    <ode>
                        <mu>0</mu>
                        <mu2>0</mu2>
                        <slip1>1.0</slip1>
                        <slip2>1.0</slip2>
                    </ode>
                </friction>
            </surface>
        </collision>

        <visual name="caster_front_visual">
            <origin xyz="0.15 0.0 -0.05" rpy="0.0 0.0 0.0"/>
            <geometry>
                <sphere radius="0.05"/>
            </geometry>
        </visual>

    </link>



    <link name="left_wheel">

        <inertial>
            <origin xyz="0.0 0.0 0.0" rpy="0.0 1.5707 1.5707"/>
            <mass value="5"/>
            <inertia ixx="0.1" ixy="0.0" ixz="0.0" iyy="0.1" iyz="0.0" izz="0.1"/>
        </inertial>

        <visual name="left_wheel_visual">
            <origin xyz="0.0 0.0 0.0" rpy="0.0 1.5707 1.5707"/>
            <geometry>
                <cylinder radius="0.1" length="0.05"/>
            </geometry>
            <material name="green"/>
        </visual>
        <collision name="left_wheel_collision">
            <origin xyz="0.0 0.0 0.0" rpy="0.0 1.5707 1.5707"/>
            <geometry>
                <cylinder radius="0.1" length="0.05"/>
            </geometry>
        </collision>
    </link>


    <link name="right_wheel">

        <inertial>
            <origin xyz="0.0 0.0 0.0" rpy="0.0 1.5707 1.5707"/>
            <mass value="5"/>
            <inertia ixx="0.1" ixy="0.0" ixz="0.0" iyy="0.1" iyz="0.0" izz="0.1"/>
        </inertial>

        <visual name="right_wheel_visual">
            <origin xyz="0.0 0.0 0.0" rpy="0.0 1.5707 1.5707"/>
            <geometry>
                <cylinder radius="0.1" length="0.05"/>
            </geometry>
            <material name="green"/>
        </visual>
        <collision name="right_wheel_collision">
            <origin xyz="0.0 0.0 0.0" rpy="0.0 1.5707 1.5707"/>
            <geometry>
                <cylinder radius="0.1" length="0.05"/>
            </geometry>
        </collision>
    </link>

    <joint name="left_wheel_hinge" type="continuous">
        <parent link="chassis"/>
        <child link="left_wheel"/>
        <axis xyz="0 1 0"/>
        <origin xyz="0 0.15 0" rpy="0 0 0"/>
        <limit effort="10000" velocity="10000"/>
        <joint_properties damping="1.0" friction="1.0"/>
    </joint>

    <joint name="right_wheel_hinge" type="continuous">
        <parent link="chassis"/>
        <child link="right_wheel"/>
        <axis xyz="0 1 0"/>
        <origin xyz="0 -0.15 0" rpy="0 0 0"/>
        <limit effort="10000" velocity="10000"/>
        <joint_properties damping="1.0" friction="1.0"/>
    </joint>

    <!-- camera -->
    <link name="camera_link">
        <collision>
            <origin xyz="0 0 0" rpy="0 0 0"/>
            <geometry>
                <box size="${cameraSize} ${cameraSize} ${cameraSize}"/>
            </geometry>
        </collision>

        <visual>
            <origin xyz="0 0 0" rpy="0 0 0"/>
            <geometry>
                <box size="${cameraSize} ${cameraSize} ${cameraSize}"/>
            </geometry>
            <material name="green"/>
        </visual>

        <inertial>
            <mass value="${cameraMass}" />
            <origin xyz="0 0 0" rpy="0 0 0"/>
            <box_inertia m="${cameraMass}" x="${cameraSize}" y="${cameraSize}" z="${cameraSize}" />
            <inertia ixx="1e-6" ixy="0" ixz="0" iyy="1e-6" iyz="0" izz="1e-6" />
        </inertial>
    </link>

    <joint name="camera_joint" type="fixed">
        <axis xyz="0 1 0" />
        <origin xyz=".2 0 0" rpy="0 0 0"/>
        <parent link="chassis"/>
        <child link="camera_link"/>
    </joint>



</robot>